Workbook

Sheet Master-BoM
B2: Bill of Materials | D2: Flood Mesh | H2: Designed By
B4: Organization: | C4: Vazworks
B5: Project ID: | C5: NA
B6: Revision: | C6: V1.0
B7: Date: | C7: 22-09-2026
B8: Variant: | C8: Flood Mesh
B10: Manufacture Part Number | C10: Description | D10: Designator | E10: Value | F10: Package (Imperial) | G10: Manufacturer | H10: Supplier | I10: Supplier Part Number | J10: Quantity
B11: Manufacturer Part Number 1 | C11: Description | D11: Designator | E11: Value | F11: Case/Package | G11: Manufacturer 1 | H11: Supplier 1 | I11: Supplier Part Number 1 | J11: Quantity
B12: LiPo Battery | D12: BT1 | J12: 1
B13: CL10A106KP8NNNC | C13: 10V 10uF X5R ±10% 0603 Multilayer Ceramic Capacitors MLCC - SMD/SMT ROHS | D13: C1, C4, C6, C17, C24, C25 | E13: 10µF | F13: 0603 | G13: Samsung Electro-Mechanics | H13: Future Electronics | I13: CL10A106KP8NNNC | J13: 6
B14: GRM188R60J106ME47D | C14: Ceramic Capacitor, Multilayer, Ceramic, 6.3V, 20% +Tol, 20% -Tol, X5R, 15% TC, 10uF, Surface Mount, 0603 | D14: C2, C19, C20 | E14: 10uF | F14: 0603 | G14: Murata | H14: DigiKey | I14: 490-3896-1-ND | J14: 3
B15: CC0402JRX7R8BB104 | C15: 25V 100nF X7R ±5% 0402 Multilayer Ceramic Capacitors MLCC - SMD/SMT ROHS | D15: C5, C7, C8, C11, C12, C13, C14, C15, C16, C18, C22, C23 | E15: 0u1 | F15: 0402 | G15: Yageo Group | H15: DigiKey | I15: 13-CC0402JRX7R8BB104CT-ND | J15: 12
B16: C0603C471J5RACAUTO | C16: 50V 470pF X7R ±5% 0603 Multilayer Ceramic Capacitors MLCC - SMD/SMT ROHS | D16: C9, C10 | E16: 470pF | F16: 0603 | G16: Yageo Group | H16: DigiKey | I16: 399-C0603C471J5RACAUTOCT-ND | J16: 2
B17: GRM188Z71C225KE43J | C17: Cap, Mlcc, 2.2Uf, X7R, 16V, 0603 Rohs Compliant: Yes |Murata GRM188Z71C225KE43J | D17: C21 | E17: 2u2 | F17: 0603 | G17: Murata | H17: DigiKey | I17: 490-GRM188Z71C225KE43JCT-ND | J17: 1
B18: ESDA7P60-1U1M | C18: TVS DIODE 5V 11.6V 1610 | D18: D1, D3 | G18: STMicroelectronics | H18: DigiKey | I18: 497-16253-1-ND | J18: 2
B19: SM4007PLTP | C19: Diode | D19: D2 | G19: MCC | H19: DigiKey | I19: SM4007PL-TPMSDKR-ND | J19: 1
B20: LTST-C195KGJRKT | D20: D4 | G20: Diodes Inc. | H20: DigiKey | I20: 160-1452-1-ND | J20: 1
B21: MPZ2012S300ATD25 | C21: FERRITE BEAD 30 OHM 0805 1LN | D21: FB1, FB2 | F21: 0805 | G21: TDK | H21: DigiKey | I21: 445-MPZ2012S300ATD25DKR-ND | J21: 2
B22: 114993390 | C22: Integrated Circuit | D22: IC1 | G22: Seeed Studio | H22: DigiKey | I22: 1597-114993390DKR-ND | J22: 1
B23: MAX17048G+T10 | C23: Integrated Circuit | D23: IC2 | G23: Analog Devices | H23: DigiKey | I23: MAX17048G+T10DKR-ND | J23: 1
B24: TPS6282533DMQR | C24: Integrated Circuit | D24: IC3 | G24: Texas Instruments | H24: DigiKey | I24: 296-TPS6282533DMQRDKR-ND | J24: 1
B25: USB4730-GF-A-KIT | C25: Connector | D25: J1 | G25: Global Connector Technology | H25: DigiKey | I25: 2073-USB4730-GF-A-KITDKR-ND | J25: 1
B26: B2B-PH-KL(LF)(SN) | C26: Connector Header, PH Series, 2 Position, 2.00mm, Shrouded Through Hole, Press-Fit, 100V, 32-24 AWG, Solder, Gray | D26: J2, J3 | G26: JST | H26: Arrow Electronics | I26: B2B-PH-KL(LF)(SN) | J26: 2
B27: 74479288147 | C27: Fixed Ind 470NH 3.1A 34 Mohm SMD | D27: L1 | F27: 1008 | G27: Wurth Elektronik | H27: DigiKey | I27: 732-9720-1-ND | J27: 1
B28: CMT-0904-85T | D28: LS1 | G28: Same Sky | H28: DigiKey | I28: 102-CMT-0904-85T-ND | J28: 1
B29: INMP441 Module | D29: MIC1 | J29: 1
B30: BC847B | C30: NPN Silicon AF Transistor, 45 V VCEO, 100 mA IC, SOT23, Reel, Green | D30: Q1 | G30: Infineon | J30: 1
B31: AC0603FR-7W5K1L | C31: Fixed Resistor, Metal Glaze/Thick Film, 0.2W, 5100ohm, 75V, 1% +/-Tol, Surface Mount, 0603 | D31: R1, R2 | E31: 5K1 | F31: 0603 | G31: Yageo Group | H31: DigiKey | I31: 13-AC0603FR-7W5K1LCT-ND | J31: 2
B32: 0402WGF2200TCE | C32: Res Thick Film 0402 220 Ohm 1% 0.063W(1/16W) ±100ppm/C Pad SMD | D32: R3 | E32: 220Ω | F32: 0402 | G32: Royal Ohm | J32: 1
B33: CRCW0402100KFKEDHP | C33: Res Thick Film 0402 100K Ohm 1% 0.2W(1/5W) ±100ppm/C Pad SMD Automotive T/R | D33: R7, R9, R18, R19 | E33: 100K | F33: 0402 | G33: Vishay | H33: DigiKey | I33: 541-100KYCT-ND | J33: 4
B34: AC0402FR-7W10KL | C34: Res Thick Film 0402 10K Ohm 1% 0.125W(1/8W) ±100ppm/C Pad SMD Automotive T/R | D34: R8, R10, R13, R14, R15, R16, R24 | E34: 10K | F34: 0402 | G34: Yageo Group | H34: DigiKey | I34: 13-AC0402FR-7W10KLDKR-ND | J34: 7
B35: ERJPA3F33R0V | C35: Res Thick Film 0603 33 Ohm 1% 0.25W(1/4W) ±100ppm/C Pad SMD Automotive T/R | D35: R17, R20, R21 | E35: 33Ω | F35: 0603 | G35: Panasonic | H35: DigiKey | I35: P33.00BYDKR-ND | J35: 3
B36: AC0603FR-7W1KL | C36: Res Thick Film 0603 1K Ohm 1% 0.2W(1/5W) ±100ppm/C Pad SMD T/R Automotive AEC-Q200 | D36: R22, R23 | E36: 1kΩ | F36: 0603 | G36: Yageo Group | H36: DigiKey | I36: 13-AC0603FR-7W1KLDKR-ND | J36: 2
B37: TS11-674-135-BK-160-RA-D | D37: S1 | G37: Same Sky | H37: DigiKey | I37: 2223-TS11-674-135-BK-160-RA-D-ND | J37: 1
B38: TS04-66-95-BK-100-SMT | D38: S2, S3, S4, S5 | G38: Same Sky | H38: DigiKey | I38: 2223-TS04-66-95-BK-100-SMT-ND | J38: 4
B39: SWS045-030R22TSK | D39: S6 | G39: Global Connector Technology | H39: DigiKey | I39: 2073-SWS045-030R22TSK-ND | J39: 1
B40: ESP32-S3-WROOM-1U-N16R8 | D40: U1 | G40: Espressif Systems | H40: DigiKey | I40: 1965-ESP32-S3-WROOM-1U-N16R8DKR-ND | J40: 1
B41: MAX98357AETE+T | C41: Tiny, Low-Cost, PCM Class D Amplifier with Class AB Performance | D41: U2 | G41: Analog Devices | H41: DigiKey | I41: MAX98357AETE+TDKR-ND | J41: 1
B42: 0.96 OLED | C42: 0.96â€ 128 X 64 MONOCHROME GRAPHIC OLED DISPLAY MODULE - I2C | D42: U3 | J42: 1
B43: MCP73833T-FCI/UN | C43: IC LI-ION/LI-POLY CTRLR 10MSOP | D43: U4 | F43: MSOP | G43: Microchip | H43: DigiKey | I43: MCP73833T-FCI/UNDKR-ND | J43: 1
...

Sheet Priced BoM
B2: Bill of Materials — Priced (India / China sources, landed cost)
B3: Flood Mesh · PCB Rev V1.0 · no voice (mic, amplifier, speaker removed) · power switch moved off-board to a panel rocker
C4: Organization: | D4: Vazworks | E4: Inputs (edit the yellow cells) | K4: Summary
C5: Designed by: | D5: NSquare Bros | E5: Build quantity (units) | H5: 15 | K5: Line items | L5: =COUNTA($C$18:$C$49) -> 32
C6: Revision: | D6: V1.0 (22-09-2026) with listed changes | E6: Exchange rate (INR per USD) | H6: 95.89 | K6: PCB parts per unit | L6: =SUMIF($F$18:$F$49,"PCB",$I$18:$I$49) -> 58
C7: Prices gathered: | D7: 27-09-2026 (search-indexed listings from Indian retailers, LCSC and Seeed; not live cart prices) | K7: Goods for the build (INR) | L7: =SUM($T$18:$T$49) -> 28889.016
K8: Shipping for the build (INR) | L8: ='Vendors & shipping'!H13 -> 2100
K9: Import duty / tax (INR) | L9: ='Vendors & shipping'!I13 -> 5265.6339
K10: Landed cost for the build (INR) | L10: =SUM($U$18:$U$49) -> 36254.65
K11: Landed cost per unit (INR) | L11: =SUM($V$18:$V$49) -> 2416.9766
K12: Landed cost per unit (USD) | L12: =SUM($V$18:$V$49)/$H$6 -> 25.205721
K13: of which PCB parts (INR) | L13: =SUMIF($F$18:$F$49,"PCB",$V$18:$V$49) -> 2189.3644
K14: of which case parts (INR) | L14: =SUMIF($F$18:$F$49,"Case",$V$18:$V$49) -> 227.61219
K15: Lines with no price yet | L15: =COUNTBLANK($M$18:$M$49) -> 1
B16: Blue = typed-in value · Black = formula · Yellow = input. Landed cost = order value (rounded up to the vendor's minimum/pack) + that vendor's shipping and import duty, shared across its lines by value. Vendor shipping and duty are set on the 'Vendors & shipping' sheet.
B17: # | C17: Manufacturer Part Number (designer) | D17: Description | E17: Designator | F17: Fitted on | G17: Value | H17: Package | I17: Qty / unit | J17: Buy from | K17: Vendor part no. / listing | L17: Part bought, if not the designer's MPN | M17: Unit price (as quoted) | N17: Currency | O17: Price tier | P17: Min / pack qty | Q17: Needed for build | R17: Order qty | S17: Unit price (INR) | T17: Order value (INR) | U17: Landed cost for build (INR) | V17: Landed cost per unit (INR) | W17: Price confidence | X17: Source | Y17: Other options checked | Z17: Change vs V1.0 BoM | AA17: Notes
B18: 1 | C18: LiPo Battery | D18: 1S LiPo, 3.7 V, 2000 mAh or more, JST-PH 2.0 mm lead (per schematic sheet 4) | E18: BT1 | F18: PCB | I18: 1 | J18: Robu.in | K18: R218004 | L18: Single-cell micro LiPo 3.7 V 2000 mAh, 2-pin JST (white) | M18: 314 | N18: INR | O18: qty 1, incl. GST | P18: 1 | Q18: =I18*$H$5 -> 15 | R18: =CEILING(Q18,MAX(1,P18)) -> 15 | S18: =IF(M18="","",IF(N18="INR",M18,M18*$H$6)) -> 314 | T18: =IF(S18="",0,R18*S18) -> 4710 | U18: =IF(T18=0,0,T18/INDEX('Vendors & shipping'!$G$7:$G$12,MATCH(J18,'Vendors & shipping'!$B$7:$B$12,0))*INDEX('Vendors & shipping'!$J$7:$J$12,MATCH(J18,'Vendors & shipping'!$B$7:$B$12,0))) -> 4710 | V18: =U18/$H$5 -> 314 | W18: MED | X18: open | Y18: ElectronicsComp KP-045060 2000 mAh ₹448.40 incl. GST (Probots lists the same model with a JST-PH 2 mm lead and protection). Alibaba 103450 about $2.00 at 10-99 pcs, but see note on importing LiPo. | AA18: Buy in India: importing LiPo cells needs BIS registration (IS 16046) and dangerous-goods shipping. CHECK the listing is JST-PH 2.0 mm (not another 'JST') with a protection circuit, and that its polarity matches J3 (README concern 2).
B19: 2 | C19: CL10A106KP8NNNC | D19: 10V 10uF X5R ±10% 0603 MLCC | E19: C1, C4, C17, C24, C25 | F19: PCB | G19: 10µF | H19: 0603 | I19: 5 | J19: LCSC | K19: C19702 | M19: 0.0065 | N19: USD | O19: 50+ | P19: 1 | Q19: =I19*$H$5 -> 75 | R19: =CEILING(Q19,MAX(1,P19)) -> 75 | S19: =IF(M19="","",IF(N19="INR",M19,M19*$H$6)) -> 0.623285 | T19: =IF(S19="",0,R19*S19) -> 46.746375 | U19: =IF(T19=0,0,T19/INDEX('Vendors & shipping'!$G$7:$G$12,MATCH(J19,'Vendors & shipping'!$B$7:$B$12,0))*INDEX('Vendors & shipping'!$J$7:$J$12,MATCH(J19,'Vendors & shipping'!$B$7:$B$12,0))) -> 75.993169 | V19: =U19/$H$5 -> 5.0662112 | W19: MED | X19: open | Y19: Other LCSC figures seen: $0.0051 at 500+, 'from' $0.0031. | Z19: 6 → 5: C6 removed (amplifier decoupling) | AA19: Same part also fills the next line's two positions.
B20: 3 | C20: GRM188R60J106ME47D | D20: 10uF 6.3V X5R ±20% 0603 MLCC | E20: C19, C20 | F20: PCB | G20: 10uF | H20: 0603 | I20: 2 | J20: LCSC | K20: C19702 | L20: CL10A106KP8NNNC (same 10 µF 0603, 10 V) | M20: 0.0065 | N20: USD | O20: 50+ | P20: 1 | Q20: =I20*$H$5 -> 30 | R20: =CEILING(Q20,MAX(1,P20)) -> 30 | S20: =IF(M20="","",IF(N20="INR",M20,M20*$H$6)) -> 0.623285 | T20: =IF(S20="",0,R20*S20) -> 18.69855 | U20: =IF(T20=0,0,T20/INDEX('Vendors & shipping'!$G$7:$G$12,MATCH(J20,'Vendors & shipping'!$B$7:$B$12,0))*INDEX('Vendors & shipping'!$J$7:$J$12,MATCH(J20,'Vendors & shipping'!$B$7:$B$12,0))) -> 30.397267 | V20: =U20/$H$5 -> 2.0264845 | W20: MED | X20: open | Y20: Same LCSC part as line 2; buy one reel strip for both lines. | Z20: 3 → 2: C2 removed (mic decoupling) | AA20: Bought as CL10A106KP8NNNC; the designer's note allows any passive of matching value and footprint.
B21: 4 | C21: CC0402JRX7R8BB104 | D21: 25V 100nF X7R ±5% 0402 MLCC | E21: C5, C8, C11, C12, C13, C14, C15, C16, C18, C22, C23 | F21: PCB | G21: 0u1 | H21: 0402 | I21: 11 | J21: LCSC | K21: C105883 | L21: YAGEO CC0402KRX7R8BB104 (100 nF 25 V X7R 0402, ±10%) | M21: 0.0008 | N21: USD | O21: 'from' price | P21: 100 | Q21: =I21*$H$5 -> 165 | R21: =CEILING(Q21,MAX(1,P21)) -> 200 | S21: =IF(M21="","",IF(N21="INR",M21,M21*$H$6)) -> 0.076712 | T21: =IF(S21="",0,R21*S21) -> 15.3424 | U21: =IF(T21=0,0,T21/INDEX('Vendors & shipping'!$G$7:$G$12,MATCH(J21,'Vendors & shipping'!$B$7:$B$12,0))*INDEX('Vendors & shipping'!$J$7:$J$12,MATCH(J21,'Vendors & shipping'!$B$7:$B$12,0))) -> 24.941348 | V21: =U21/$H$5 -> 1.6627565 | W21: MED | X21: open | Y21: Exact ±5% MPN not on LCSC. CL05B104KO5NNNC (C1525) is cheaper but only 16 V. | Z21: 12 → 11: C7 removed (amplifier decoupling) | AA21: ±10% instead of ±5%: fine for decoupling.
B22: 5 | C22: GRM188Z71C225KE43J | D22: 2.2uF 16V X7R 0603 MLCC | E22: C21 | F22: PCB | G22: 2u2 | H22: 0603 | I22: 1 | J22: LCSC | K22: C21794833 | M22: 0.0172 | N22: USD | O22: 'from' price | P22: 1 | Q22: =I22*$H$5 -> 15 | R22: =CEILING(Q22,MAX(1,P22)) -> 15 | S22: =IF(M22="","",IF(N22="INR",M22,M22*$H$6)) -> 1.649308 | T22: =IF(S22="",0,R22*S22) -> 24.73962 | U22: =IF(T22=0,0,T22/INDEX('Vendors & shipping'!$G$7:$G$12,MATCH(J22,'Vendors & shipping'!$B$7:$B$12,0))*INDEX('Vendors & shipping'!$J$7:$J$12,MATCH(J22,'Vendors & shipping'!$B$7:$B$12,0))) -> 40.217923 | V22: =U22/$H$5 -> 2.6811949 | W22: HIGH | X22: open | Y22: CL10A225KO8NNNC (C23630) $0.0085 is X5R, not X7R.
B23: 6 | C23: ESDA7P60-1U1M | D23: TVS diode 5V 11.6V 1610 | E23: D1, D3 | F23: PCB | I23: 2 | J23: LCSC | K23: C1975146 | M23: 0.0944 | N23: USD | O23: 'from' price | P23: 1 | Q23: =I23*$H$5 -> 30 | R23: =CEILING(Q23,MAX(1,P23)) -> 30 | S23: =IF(M23="","",IF(N23="INR",M23,M23*$H$6)) -> 9.052016 | T23: =IF(S23="",0,R23*S23) -> 271.56048 | U23: =IF(T23=0,0,T23/INDEX('Vendors & shipping'!$G$7:$G$12,MATCH(J23,'Vendors & shipping'!$B$7:$B$12,0))*INDEX('Vendors & shipping'!$J$7:$J$12,MATCH(J23,'Vendors & shipping'!$B$7:$B$12,0))) -> 441.46185 | V23: =U23/$H$5 -> 29.43079 | W23: MED | X23: open | Y23: TECH PUBLIC second-source ESDA7P60-1U1M (C7202956) from $0.0412. No Indian retailer price for the -60 part.
B24: 7 | C24: SM4007PLTP | D24: Diode 1000V 1A SOD-123FL (buzzer flyback) | E24: D2 | F24: PCB | I24: 1 | J24: LCSC | K24: C64898 | L24: MDD SM4007PL (1 A 1 kV, SOD-123FL) | M24: 0.0032 | N24: USD | O24: 'from' price | P24: 50 | Q24: =I24*$H$5 -> 15 | R24: =CEILING(Q24,MAX(1,P24)) -> 50 | S24: =IF(M24="","",IF(N24="INR",M24,M24*$H$6)) -> 0.306848 | T24: =IF(S24="",0,R24*S24) -> 15.3424 | U24: =IF(T24=0,0,T24/INDEX('Vendors & shipping'!$G$7:$G$12,MATCH(J24,'Vendors & shipping'!$B$7:$B$12,0))*INDEX('Vendors & shipping'!$J$7:$J$12,MATCH(J24,'Vendors & shipping'!$B$7:$B$12,0))) -> 24.941348 | V24: =U24/$H$5 -> 1.6627565 | W24: MED | X24: open | Y24: MCC SM4007PL-TP (C78741) $0.0551, min 50. | AA24: Orderable MPN is written SM4007PL-TP.
B25: 8 | C25: LTST-C195KGJRKT | D25: LED red/green bicolour 0606 (charge status) | E25: D4 | F25: PCB | I25: 1 | J25: LCSC | K25: C125104 | M25: 0.0123 | N25: USD | O25: 'from' price | P25: 1 | Q25: =I25*$H$5 -> 15 | R25: =CEILING(Q25,MAX(1,P25)) -> 15 | S25: =IF(M25="","",IF(N25="INR",M25,M25*$H$6)) -> 1.179447 | T25: =IF(S25="",0,R25*S25) -> 17.691705 | U25: =IF(T25=0,0,T25/INDEX('Vendors & shipping'!$G$7:$G$12,MATCH(J25,'Vendors & shipping'!$B$7:$B$12,0))*INDEX('Vendors & shipping'!$J$7:$J$12,MATCH(J25,'Vendors & shipping'!$B$7:$B$12,0))) -> 28.760491 | V25: =U25/$H$5 -> 1.9173661 | W25: HIGH | X25: open | AA25: Designer's BoM says 'Diodes Inc.'; LTST-C195KGJRKT is a Lite-On part.
B26: 9 | C26: 114993390 | D26: Seeed Wio-SX1262 LoRa module | E26: IC1 | F26: PCB | I26: 1 | J26: Seeed Studio | K26: 114993390 | M26: 4.29 | N26: USD | O26: qty 1 and 10+ | P26: 1 | Q26: =I26*$H$5 -> 15 | R26: =CEILING(Q26,MAX(1,P26)) -> 15 | S26: =IF(M26="","",IF(N26="INR",M26,M26*$H$6)) -> 411.3681 | T26: =IF(S26="",0,R26*S26) -> 6170.5215 | U26: =IF(T26=0,0,T26/INDEX('Vendors & shipping'!$G$7:$G$12,MATCH(J26,'Vendors & shipping'!$B$7:$B$12,0))*INDEX('Vendors & shipping'!$J$7:$J$12,MATCH(J26,'Vendors & shipping'!$B$7:$B$12,0))) -> 8083.3832 | V26: =U26/$H$5 -> 538.89221 | W26: HIGH | X26: open | Y26: Not on LCSC. No Indian retailer price for the bare module (ThinkRobotics lists it); Robocraze sells only a XIAO + Wio-SX1262 kit at ₹1,699. | AA26: RF comes out on the module's own IPEX (U.FL) connector, so its ANT pad is unconnected, as on the schematic. Needs an 865-867 MHz U.FL antenna (not in this BoM).
B27: 10 | C27: MAX17048G+T10 | D27: Li-ion fuel gauge, I²C, 8-TDFN | E27: IC2 | F27: PCB | I27: 1 | J27: LCSC | K27: C2682616 | M27: 1.3385 | N27: USD | O27: 'from' price | P27: 1 | Q27: =I27*$H$5 -> 15 | R27: =CEILING(Q27,MAX(1,P27)) -> 15 | S27: =IF(M27="","",IF(N27="INR",M27,M27*$H$6)) -> 128.34876 | T27: =IF(S27="",0,R27*S27) -> 1925.2315 | U27: =IF(T27=0,0,T27/INDEX('Vendors & shipping'!$G$7:$G$12,MATCH(J27,'Vendors & shipping'!$B$7:$B$12,0))*INDEX('Vendors & shipping'!$J$7:$J$12,MATCH(J27,'Vendors & shipping'!$B$7:$B$12,0))) -> 3129.7494 | V27: =U27/$H$5 -> 208.64996 | W27: MED | X27: open | Y27: Evelta ₹507.45 ex GST.
B28: 11 | C28: TPS6282533DMQR | D28: 3.3 V 2 A buck converter, 6-VSON | E28: IC3 | F28: PCB | I28: 1 | J28: LCSC | K28: C2650334 | L28: TPS62825DMQR (adjustable version, same package) - needs a PCB change | M28: 0.3554 | N28: USD | O28: 'from' price | P28: 1 | Q28: =I28*$H$5 -> 15 | R28: =CEILING(Q28,MAX(1,P28)) -> 15 | S28: =IF(M28="","",IF(N28="INR",M28,M28*$H$6)) -> 34.079306 | T28: =IF(S28="",0,R28*S28) -> 511.18959 | U28: =IF(T28=0,0,T28/INDEX('Vendors & shipping'!$G$7:$G$12,MATCH(J28,'Vendors & shipping'!$B$7:$B$12,0))*INDEX('Vendors & shipping'!$J$7:$J$12,MATCH(J28,'Vendors & shipping'!$B$7:$B$12,0))) -> 831.01453 | V28: =U28/$H$5 -> 55.400968 | W28: MED | X28: open | Y28: The fixed-3.3 V TPS6282533DMQR is only sold by TI.com and US distributors; not on LCSC, JLCPCB, Evelta, Robu, ElectronicsComp or Lion Circuits. | AA28: CHECK (designer): no non-US source for the fixed 3.3 V part. Priced as the adjustable TPS62825DMQR, which needs a two-resistor feedback divider on FB. The board is being revised anyway, so this is the moment to decide.
B29: 12 | C29: USB4730-GF-A-KIT | D29: USB-C receptacle (charging only) | E29: J1 | F29: PCB | I29: 1 | J29: JLCPCB (assembly only) | K29: C20598701 | N29: USD | P29: 1 | Q29: =I29*$H$5 -> 15 | R29: =CEILING(Q29,MAX(1,P29)) -> 15 | S29: =IF(M29="","",IF(N29="INR",M29,M29*$H$6)) | T29: =IF(S29="",0,R29*S29) -> 0 | U29: =IF(T29=0,0,T29/INDEX('Vendors & shipping'!$G$7:$G$12,MATCH(J29,'Vendors & shipping'!$B$7:$B$12,0))*INDEX('Vendors & shipping'!$J$7:$J$12,MATCH(J29,'Vendors & shipping'!$B$7:$B$12,0))) -> 0 | V29: =U29/$H$5 -> 0 | W29: LOW | X29: open | Y29: Not sold loose by LCSC or Indian retailers; only JLCPCB assembly and US distributors. The common LCSC USB-C (HRO TYPE-C-31-M-12, C165948, $0.097) is NOT sealed and has a different footprint. | AA29: IP67-sealed USB-C (GCT specification): the case's seal at the charging port relies on it, so an unsealed LCSC connector is not a drop-in. Buy loose from a US distributor, have JLCPCB assemble the board, or the designer picks a sealed USB-C that LCSC stocks.
B30: 13 | C30: B2B-PH-KL(LF)(SN) | D30: JST PH 2-pin 2.00 mm shrouded TH header (battery) | E30: J3 | F30: PCB | I30: 1 | J30: LCSC | K30: C2683610 | M30: 0.0337 | N30: USD | O30: 'from' price | P30: 1 | Q30: =I30*$H$5 -> 15 | R30: =CEILING(Q30,MAX(1,P30)) -> 15 | S30: =IF(M30="","",IF(N30="INR",M30,M30*$H$6)) -> 3.231493 | T30: =IF(S30="",0,R30*S30) -> 48.472395 | U30: =IF(T30=0,0,T30/INDEX('Vendors & shipping'!$G$7:$G$12,MATCH(J30,'Vendors & shipping'!$B$7:$B$12,0))*INDEX('Vendors & shipping'!$J$7:$J$12,MATCH(J30,'Vendors & shipping'!$B$7:$B$12,0))) -> 78.79907 | V30: =U30/$H$5 -> 5.2532713 | W30: HIGH | X30: open | Y30: Sunrom 2-pin PH header ₹2.25 (shroud not confirmed). | Z30: 2 → 1: J2 removed (speaker connector)
B31: 14 | C31: 74479288147 | D31: Fixed inductor 470 nH 3.1 A 34 mΩ, 1008 (buck) | E31: L1 | F31: PCB | H31: 1008 | I31: 1 | J31: LCSC | K31: C703140 | L31: Murata DFE252012F-R47M=P2 (470 nH ±20%, 4.9 A, 2520/1008) | M31: 0.0961 | N31: USD | O31: 'from' price | P31: 1 | Q31: =I31*$H$5 -> 15 | R31: =CEILING(Q31,MAX(1,P31)) -> 15 | S31: =IF(M31="","",IF(N31="INR",M31,M31*$H$6)) -> 9.215029 | T31: =IF(S31="",0,R31*S31) -> 138.22544 | U31: =IF(T31=0,0,T31/INDEX('Vendors & shipping'!$G$7:$G$12,MATCH(J31,'Vendors & shipping'!$B$7:$B$12,0))*INDEX('Vendors & shipping'!$J$7:$J$12,MATCH(J31,'Vendors & shipping'!$B$7:$B$12,0))) -> 224.70595 | V31: =U31/$H$5 -> 14.980397 | W31: MED | X31: open | Y31: The Würth part is not on LCSC. | AA31: CHECK: pads of the Murata part against the Würth footprint. The Würth datasheet (6.8 A, 22 mΩ) also disagrees with the BoM text (3.1 A, 34 mΩ).
B32: 15 | C32: CMT-0904-85T | D32: Magnetic buzzer (needs PWM tone) | E32: LS1 | F32: PCB | I32: 1 | J32: LCSC | K32: C3811834 | M32: 0.953 | N32: USD | O32: 'from' price | P32: 1 | Q32: =I32*$H$5 -> 15 | R32: =CEILING(Q32,MAX(1,P32)) -> 15 | S32: =IF(M32="","",IF(N32="INR",M32,M32*$H$6)) -> 91.38317 | T32: =IF(S32="",0,R32*S32) -> 1370.7476 | U32: =IF(T32=0,0,T32/INDEX('Vendors & shipping'!$G$7:$G$12,MATCH(J32,'Vendors & shipping'!$B$7:$B$12,0))*INDEX('Vendors & shipping'!$J$7:$J$12,MATCH(J32,'Vendors & shipping'!$B$7:$B$12,0))) -> 2228.3535 | V32: =U32/$H$5 -> 148.5569 | W32: HIGH | X32: open | Y32: 88 in stock when searched. Indian retailers had only 5 V buzzers of unknown size or an 8.5 mm SMD passive (Probots ₹95); neither fits this footprint. | AA32: Kept: alarm tone. Not part of the voice path.
B33: 16 | C33: BC847B | D33: NPN 45 V 100 mA SOT-23 (buzzer driver) | E33: Q1 | F33: PCB | I33: 1 | J33: LCSC | K33: C181140 | L33: BC847B, Guangdong Hottech (SOT-23) | M33: 0.0054 | N33: USD | O33: 'from' price | P33: 1 | Q33: =I33*$H$5 -> 15 | R33: =CEILING(Q33,MAX(1,P33)) -> 15 | S33: =IF(M33="","",IF(N33="INR",M33,M33*$H$6)) -> 0.517806 | T33: =IF(S33="",0,R33*S33) -> 7.76709 | U33: =IF(T33=0,0,T33/INDEX('Vendors & shipping'!$G$7:$G$12,MATCH(J33,'Vendors & shipping'!$B$7:$B$12,0))*INDEX('Vendors & shipping'!$J$7:$J$12,MATCH(J33,'Vendors & shipping'!$B$7:$B$12,0))) -> 12.626557 | V33: =U33/$H$5 -> 0.84177048 | W33: HIGH | X33: open | Y33: Nexperia BC847B,215 is JLCPCB C57668 (price not found). | AA33: Generic BC847B; the Infineon part is being discontinued (last order 31-12-2026).
B34: 17 | C34: AC0603FR-7W5K1L | D34: 5.1 kΩ 1% 0603 (USB-C CC pull-downs) | E34: R1, R2 | F34: PCB | G34: 5K1 | H34: 0603 | I34: 2 | J34: LCSC | K34: C23186 | L34: UNI-ROYAL 0603WAF5101T5E (5.1 kΩ 1% 0603) | M34: 0.0016 | N34: USD | O34: 'from' price | P34: 100 | Q34: =I34*$H$5 -> 30 | R34: =CEILING(Q34,MAX(1,P34)) -> 100 | S34: =IF(M34="","",IF(N34="INR",M34,M34*$H$6)) -> 0.153424 | T34: =IF(S34="",0,R34*S34) -> 15.3424 | U34: =IF(T34=0,0,T34/INDEX('Vendors & shipping'!$G$7:$G$12,MATCH(J34,'Vendors & shipping'!$B$7:$B$12,0))*INDEX('Vendors & shipping'!$J$7:$J$12,MATCH(J34,'Vendors & shipping'!$B$7:$B$12,0))) -> 24.941348 | V34: =U34/$H$5 -> 1.6627565 | W34: MED | X34: open | AA34: Lower power rating than the -7W part; this resistor dissipates well under 10 mW.
B35: 18 | C35: 0402WGF2200TCE | D35: 220 Ω 1% 0402 (buzzer base) | E35: R3 | F35: PCB | G35: 220Ω | H35: 0402 | I35: 1 | J35: LCSC | K35: C25091 | M35: 0.002 | N35: USD | O35: 'from' price | P35: 100 | Q35: =I35*$H$5 -> 15 | R35: =CEILING(Q35,MAX(1,P35)) -> 100 | S35: =IF(M35="","",IF(N35="INR",M35,M35*$H$6)) -> 0.19178 | T35: =IF(S35="",0,R35*S35) -> 19.178 | U35: =IF(T35=0,0,T35/INDEX('Vendors & shipping'!$G$7:$G$12,MATCH(J35,'Vendors & shipping'!$B$7:$B$12,0))*INDEX('Vendors & shipping'!$J$7:$J$12,MATCH(J35,'Vendors & shipping'!$B$7:$B$12,0))) -> 31.176685 | V35: =U35/$H$5 -> 2.0784456 | W35: HIGH | X35: open | AA35: No supplier in the designer's BoM.
B36: 19 | C36: CRCW0402100KFKEDHP | D36: 100 kΩ 1% 0402 | E36: R18, R19 | F36: PCB | G36: 100K | H36: 0402 | I36: 2 | J36: LCSC | K36: C25741 | L36: UNI-ROYAL 0402WGF1003TCE (100 kΩ 1% 0402) | M36: 0.0013 | N36: USD | O36: 'from' price | P36: 100 | Q36: =I36*$H$5 -> 30 | R36: =CEILING(Q36,MAX(1,P36)) -> 100 | S36: =IF(M36="","",IF(N36="INR",M36,M36*$H$6)) -> 0.124657 | T36: =IF(S36="",0,R36*S36) -> 12.4657 | U36: =IF(T36=0,0,T36/INDEX('Vendors & shipping'!$G$7:$G$12,MATCH(J36,'Vendors & shipping'!$B$7:$B$12,0))*INDEX('Vendors & shipping'!$J$7:$J$12,MATCH(J36,'Vendors & shipping'!$B$7:$B$12,0))) -> 20.264845 | V36: =U36/$H$5 -> 1.3509897 | W36: MED | X36: open | Y36: Another figure seen: $0.0005. | Z36: 4 → 2: R7 (SD_MODE) and R9 (GAIN_SLOT) removed | AA36: Pull-up: power rating irrelevant.
B37: 20 | C37: AC0402FR-7W10KL | D37: 10 kΩ 1% 0402 | E37: R8, R10, R13, R14, R15, R16, R24 | F37: PCB | G37: 10K | H37: 0402 | I37: 7 | J37: LCSC | K37: C25744 | L37: UNI-ROYAL 0402WGF1002TCE (10 kΩ 1% 0402) | M37: 0.0009 | N37: USD | O37: 'from' price | P37: 100 | Q37: =I37*$H$5 -> 105 | R37: =CEILING(Q37,MAX(1,P37)) -> 200 | S37: =IF(M37="","",IF(N37="INR",M37,M37*$H$6)) -> 0.086301 | T37: =IF(S37="",0,R37*S37) -> 17.2602 | U37: =IF(T37=0,0,T37/INDEX('Vendors & shipping'!$G$7:$G$12,MATCH(J37,'Vendors & shipping'!$B$7:$B$12,0))*INDEX('Vendors & shipping'!$J$7:$J$12,MATCH(J37,'Vendors & shipping'!$B$7:$B$12,0))) -> 28.059016 | V37: =U37/$H$5 -> 1.8706011 | W37: MED | X37: open | Y37: One result said out of stock; any 10 kΩ 1% 0402 will do.
B38: 21 | C38: ERJPA3F33R0V | D38: 33 Ω 1% 0603 (LoRa SPI series) | E38: R17, R20, R21 | F38: PCB | G38: 33Ω | H38: 0603 | I38: 3 | J38: LCSC | K38: C23140 | L38: UNI-ROYAL 0603WAF330JT5E (33 Ω 1% 0603) | M38: 0.001 | N38: USD | O38: 'from' price | P38: 100 | Q38: =I38*$H$5 -> 45 | R38: =CEILING(Q38,MAX(1,P38)) -> 100 | S38: =IF(M38="","",IF(N38="INR",M38,M38*$H$6)) -> 0.09589 | T38: =IF(S38="",0,R38*S38) -> 9.589 | U38: =IF(T38=0,0,T38/INDEX('Vendors & shipping'!$G$7:$G$12,MATCH(J38,'Vendors & shipping'!$B$7:$B$12,0))*INDEX('Vendors & shipping'!$J$7:$J$12,MATCH(J38,'Vendors & shipping'!$B$7:$B$12,0))) -> 15.588342 | V38: =U38/$H$5 -> 1.0392228 | W38: MED | X38: open | AA38: SPI series resistor: the original's 0.25 W anti-surge rating is not needed.
B39: 22 | C39: AC0603FR-7W1KL | D39: 1 kΩ 1% 0603 (LED) | E39: R22, R23 | F39: PCB | G39: 1kΩ | H39: 0603 | I39: 2 | J39: LCSC | K39: C21190 | L39: UNI-ROYAL 0603WAF1001T5E (1 kΩ 1% 0603) | M39: 0.0017 | N39: USD | O39: 'from' price | P39: 100 | Q39: =I39*$H$5 -> 30 | R39: =CEILING(Q39,MAX(1,P39)) -> 100 | S39: =IF(M39="","",IF(N39="INR",M39,M39*$H$6)) -> 0.163013 | T39: =IF(S39="",0,R39*S39) -> 16.3013 | U39: =IF(T39=0,0,T39/INDEX('Vendors & shipping'!$G$7:$G$12,MATCH(J39,'Vendors & shipping'!$B$7:$B$12,0))*INDEX('Vendors & shipping'!$J$7:$J$12,MATCH(J39,'Vendors & shipping'!$B$7:$B$12,0))) -> 26.500182 | V39: =U39/$H$5 -> 1.7666788 | W39: MED | X39: open
B40: 23 | C40: TS11-674-135-BK-160-RA-D | D40: Tactile switch, right angle (side / SOS button) | E40: S1 | F40: PCB | I40: 1 | J40: LCSC | K40: C6290621 | L40: TS11-674-50-BK-260-RA-D (same series, shorter actuator, 260 gf) | M40: 0.082 | N40: USD | O40: 'from' price | P40: 1 | Q40: =I40*$H$5 -> 15 | R40: =CEILING(Q40,MAX(1,P40)) -> 15 | S40: =IF(M40="","",IF(N40="INR",M40,M40*$H$6)) -> 7.86298 | T40: =IF(S40="",0,R40*S40) -> 117.9447 | U40: =IF(T40=0,0,T40/INDEX('Vendors & shipping'!$G$7:$G$12,MATCH(J40,'Vendors & shipping'!$B$7:$B$12,0))*INDEX('Vendors & shipping'!$J$7:$J$12,MATCH(J40,'Vendors & shipping'!$B$7:$B$12,0))) -> 191.73661 | V40: =U40/$H$5 -> 12.782441 | W40: LOW | X40: open | Y40: Out of stock at LCSC when searched. The -135 part is only at US distributors. JLCPCB lists TS11-674-80-BK-260-RA-D (C7074162) for assembly. | AA40: CHECK (designer): the side SOS button's actuator length sets how far it pokes through the case. The stocked TS11 variants are shorter; pick one and adjust the case, or buy the -135 from a US distributor.
B41: 24 | C41: TS04-66-95-BK-100-SMT | D41: Tactile switch, SMT (face buttons) | E41: S2, S3, S4, S5 | F41: PCB | I41: 4 | J41: LCSC | K41: C20183374 | L41: TS04-66-85-BK-260-SMT-TR (same series, 8.5 mm tall, 260 gf) | M41: 0.1244 | N41: USD | O41: 'from' price | P41: 1 | Q41: =I41*$H$5 -> 60 | R41: =CEILING(Q41,MAX(1,P41)) -> 60 | S41: =IF(M41="","",IF(N41="INR",M41,M41*$H$6)) -> 11.928716 | T41: =IF(S41="",0,R41*S41) -> 715.72296 | U41: =IF(T41=0,0,T41/INDEX('Vendors & shipping'!$G$7:$G$12,MATCH(J41,'Vendors & shipping'!$B$7:$B$12,0))*INDEX('Vendors & shipping'!$J$7:$J$12,MATCH(J41,'Vendors & shipping'!$B$7:$B$12,0))) -> 1163.5139 | V41: =U41/$H$5 -> 77.567591 | W41: MED | X41: open | Y41: JLCPCB lists the 9.5 mm TS04-66-95-BK-260-SMT (C9900020841) for assembly. ElectronicsComp sells a generic 6×6×9.5 mm SMD switch (5-pack, price not found) and a 6×6×4.3 mm one at ₹29 per 5 ex GST. | AA41: CHECK: 1 mm shorter and stiffer than specified; confirm against the case, or use JLCPCB's 9.5 mm part if JLCPCB assembles the board.
...

Sheet Vendors & shipping
B2: Vendors & shipping
B3: Shipping is charged per order, so each vendor's fee and import duty are shared across the lines bought from it. Edit the yellow cells if a vendor's terms differ at checkout.
B4: Duty / tax added: 0% for Indian shops whose prices include GST; 18% for Indian shops that quote ex-GST; the customs estimate for imports, applied to goods + shipping.
B6: Vendor | C6: Ships from | D6: Shipping fee (INR) | E6: Free shipping from (INR) | F6: Duty / tax added (%) | G6: Order subtotal (INR) | H6: Shipping charged (INR) | I6: Duty / tax (INR) | J6: Landed total (INR) | K6: Lines | L6: Basis for the fee and duty
B7: LCSC | C7: China | D7: 2100 | E7: 0 | F7: 0.31 | G7: =SUMIF('Priced BoM'!$J$18:$J$49,B7,'Priced BoM'!$T$18:$T$49) -> 8715.3942 | H7: =IF(G7=0,0,IF(AND(E7>0,G7>=E7),0,D7)) -> 2100 | I7: =(G7+H7)*F7 -> 3352.7722 | J7: =G7+H7+I7 -> 14168.166 | K7: =COUNTIF('Priced BoM'!$J$18:$J$49,B7) -> 26 | L7: Fee: DHL Express to India is about $12-25 (₹1,000-2,100) for a small parcel (zbotic.in cost guide; LCSC shows the exact figure in the cart), upper figure used. Duty: LCSC ships DAP, the buyer pays on arrival. Courier imports for personal use (CTH 9804) pay 10% BCD + 10% SWS on it + 18% IGST ≈ 31% from 1 Apr 2026; business imports are typically 25-35%. India has no duty-free threshold. Parcels with chips need a CHIMS registration (imports.gov.in) and DHL KYC before clearance.
B8: Seeed Studio | C8: China | D8: 0 | E8: 4795 | F8: 0.31 | G8: =SUMIF('Priced BoM'!$J$18:$J$49,B8,'Priced BoM'!$T$18:$T$49) -> 6170.5215 | H8: =IF(G8=0,0,IF(AND(E8>0,G8>=E8),0,D8)) -> 0 | I8: =(G8+H8)*F8 -> 1912.8617 | J8: =G8+H8+I8 -> 8083.3832 | K8: =COUNTIF('Priced BoM'!$J$18:$J$49,B8) -> 1 | L8: Free Registered Air Mail on orders over $50 (₹4,795); fee below that not found. Ships DAP, so the same ≈31% duty and IGST applies on arrival.
B9: Evelta | C9: India (Mumbai) | D9: 53 | E9: 1180 | F9: 0 | G9: =SUMIF('Priced BoM'!$J$18:$J$49,B9,'Priced BoM'!$T$18:$T$49) -> 7133.1 | H9: =IF(G9=0,0,IF(AND(E9>0,G9>=E9),0,D9)) -> 0 | I9: =(G9+H9)*F9 -> 0 | J9: =G9+H9+I9 -> 7133.1 | K9: =COUNTIF('Priced BoM'!$J$18:$J$49,B9) -> 2 | L9: Free shipping above ₹1,000 before GST (≈ ₹1,180 incl. GST); otherwise ₹45 + GST. Prices used include GST.
B10: Robu.in | C10: India | D10: 0 | E10: 499 | F10: 0 | G10: =SUMIF('Priced BoM'!$J$18:$J$49,B10,'Priced BoM'!$T$18:$T$49) -> 4710 | H10: =IF(G10=0,0,IF(AND(E10>0,G10>=E10),0,D10)) -> 0 | I10: =(G10+H10)*F10 -> 0 | J10: =G10+H10+I10 -> 4710 | K10: =COUNTIF('Priced BoM'!$J$18:$J$49,B10) -> 1 | L10: Free shipping above ₹499 (Robu pages disagree; one says free on all orders). The fee below ₹499 was not found. Prices include GST.
B11: Quartz Components | C11: India | D11: 0 | E11: 500 | F11: 0 | G11: =SUMIF('Priced BoM'!$J$18:$J$49,B11,'Priced BoM'!$T$18:$T$49) -> 2160 | H11: =IF(G11=0,0,IF(AND(E11>0,G11>=E11),0,D11)) -> 0 | I11: =(G11+H11)*F11 -> 0 | J11: =G11+H11+I11 -> 2160 | K11: =COUNTIF('Priced BoM'!$J$18:$J$49,B11) -> 1 | L11: Free shipping on prepaid orders above ₹500; fee below that not found. Price assumed GST-inclusive (not stated); add 18% here if the cart shows GST on top.
B12: JLCPCB (assembly only) | C12: China | D12: 0 | E12: 0 | F12: 0.31 | G12: =SUMIF('Priced BoM'!$J$18:$J$49,B12,'Priced BoM'!$T$18:$T$49) -> 0 | H12: =IF(G12=0,0,IF(AND(E12>0,G12>=E12),0,D12)) -> 0 | I12: =(G12+H12)*F12 -> 0 | J12: =G12+H12+I12 -> 0 | K12: =COUNTIF('Priced BoM'!$J$18:$J$49,B12) -> 1 | L12: JLCPCB stocks the sealed USB4730 only for boards it assembles; the part is not shipped loose. Price not found, so the line is left blank.
B13: Total | G13: =SUM(G7:G12) -> 28889.016 | H13: =SUM(H7:H12) -> 2100 | I13: =SUM(I7:I12) -> 5265.6339 | J13: =SUM(J7:J12) -> 36254.65 | K13: =SUM(K7:K12) -> 32
B14: Check: every BoM line has a vendor on this sheet | K14: =IF(K13=COUNTA('Priced BoM'!$C$18:$C$49),"OK","MISSING") -> OK

Sheet Changes vs V1.0
B2: Removed from the designer's V1.0 BoM
B3: Voice parts (MIC and SPEAKER blocks, schematic sheet 1) and the on-board power switch S6 (schematic sheet 4). The buzzer (LS1, Q1, R3, D2) stays.
B5: Designator | C5: Manufacturer Part Number | D5: Value / part | E5: Qty | F5: Schematic block | G5: What it did / why removed | H5: Effect on V1.0 BoM line
B6: MIC1 | C6: INMP441 Module | D6: I²S MEMS microphone module | E6: 1 | F6: MIC | G6: Voice capture | H6: Line deleted
B7: C2 | C7: GRM188R60J106ME47D | D7: 10uF 0603 | E7: 1 | F7: MIC | G7: Mic VDD decoupling | H7: Line qty 3 → 2
B8: U2 | C8: MAX98357AETE+T | D8: I²S class-D amplifier | E8: 1 | F8: SPEAKER | G8: Speaker drive | H8: Line deleted
B9: C6 | C9: CL10A106KP8NNNC | D9: 10µF 0603 | E9: 1 | F9: SPEAKER | G9: Amplifier VDD bulk decoupling | H9: Line qty 6 → 5
B10: C7 | C10: CC0402JRX7R8BB104 | D10: 100nF 0402 | E10: 1 | F10: SPEAKER | G10: Amplifier VDD decoupling | H10: Line qty 12 → 11
B11: R7 | C11: CRCW0402100KFKEDHP | D11: 100K 0402 | E11: 1 | F11: SPEAKER | G11: SD_MODE (SPK_SD) resistor to 3V3 | H11: Line qty 4 → 2 (with R9)
B12: R9 | C12: CRCW0402100KFKEDHP | D12: 100K 0402 | E12: 1 | F12: SPEAKER | G12: GAIN_SLOT to GND (gain select) | H12: Line qty 4 → 2 (with R7)
B13: FB1, FB2 | C13: MPZ2012S300ATD25 | D13: Ferrite bead 30 Ω 0805 | E13: 2 | F13: SPEAKER | G13: Speaker output EMI filter | H13: Line deleted
B14: C9, C10 | C14: C0603C471J5RACAUTO | D14: 470pF 0603 | E14: 2 | F14: SPEAKER | G14: Speaker output EMI filter | H14: Line deleted (BoM lists Yageo; this MPN is KEMET)
B15: J2 | C15: B2B-PH-KL(LF)(SN) | D15: JST PH 2-pin header | E15: 1 | F15: SPEAKER | G15: Speaker connector | H15: Line qty 2 → 1
B16: S6 | C16: SWS045-030R22TSK | D16: Slide switch, 2 poles in parallel | E16: 1 | F16: POWER (sheet 4) | G16: Power on/off between BATT+ and BATT_IN. Replaced by a panel-mounted rocker on the case, wired to a new 2-pin header (owner decision, 27-09-2026) | H16: Line deleted
D17: Total removed | E17: =SUM(E6:E16) -> 13
B20: Added
B21: New lines on the Priced BoM sheet.
B23: Designator | C23: Part | D23: Description | E23: Qty | F23: Fitted on | G23: Why | H23: Effect on BoM
B24: J_SW (new) | C24: BM02B-GHS-TBT | D24: JST GH 2-pin SMT header, latching | E24: 1 | F24: PCB | G24: Takes BATT+ and BATT_IN to the case rocker in place of S6. GH, so the battery's PH plug cannot be put in it. | H24: New line
B25: SW1 (case) | C25: KCD1-2-101W | D25: Waterproof (IP65) snap-in mini rocker, SPST | E25: 1 | F25: Case | G25: Power switch on the case wall (owner decision, 27-09-2026) | H25: New line
B26: Switch lead | C26: GHR-02V-S | D26: JST GH 2-pin housing | E26: 1 | F26: Case | G26: Plug for the switch lead | H26: New line
B27: Switch lead | C27: SSHL-002T-P0.2 | D27: JST GH crimp contacts | E27: 2 | F27: Case | G27: Crimped onto the switch lead wires | H27: New line
B28: ANT1 (case) | C28: 1461530100 | D28: 2.4 GHz adhesive FPC antenna, U.FL/MHF1 | E28: 1 | F28: Case | G28: The WROOM-1U has no antenna of its own; Bluetooth provisioning and firmware updates (over Bluetooth) need one | H28: New line
D29: Added on the PCB | E29: =SUMIF(F24:F28,"PCB",E24:E28) -> 1
D31: Check: V1.0 − removed + added | E31: ='Master-BoM'!J44-E17+E29 -> 58 | F31: =IF(E31=SUMIF('Priced BoM'!$F$18:$F$49,"PCB",'Priced BoM'!$I$18:$I$49),"matches Priced BoM PCB parts","MISMATCH") -> matches Priced BoM PCB parts
B33: DNP footprints in the removed blocks (not in the BoM, remove from the PCB layout): R6 (GAIN_SLOT pull-up), TP3 (SPK_SD test point).
B34: GPIOs freed on U1: IO4, IO5, IO6 (speaker I²S), IO15, IO16, IO17 (mic I²S), IO18 (SPK_SD), all RTC-capable. architecture.md §9 item 8 considers them for a direct keypad matrix.
B37: Design notes for the switch and antenna changes
B38: 1. Power switch: put J_SW in the BATT+ → BATT_IN break exactly where S6 was, not in series with J3. Then the charger on BATT+ still charges the battery with the rocker OFF, as before. No firmware change: the MCU never sensed S6.
B39: 2. Why not a second JST-PH 2-pin: the battery and switch plugs could be swapped. With the battery in the switch header and the switch lead in J3, turning the rocker ON ties BATT+ to GND and drives BATT_IN below GND through the buck's and fuel gauge's internal diodes, limited only by the pack. A JST-XH header or a PH 3-pin header does not prevent this, because a PH plug still fits their shrouds. JST GH or ZH does.
B40: 3. Switch-on ringing: the lead adds inductance in front of C21 (2.2 µF), and TI's TPS6282x datasheet shows 4.7 µF at the input. Raise C21 to at least 4.7 µF and add some bulk capacitance on BATT_IN at J_SW. Check BATT_IN on a scope over about 20 switch-ons with a full cell (the buck's VIN absolute maximum is 6 V).
B41: 4. Fuel gauge: it still sits on BATT_IN, after the switch, and now also sees the lead and contact resistance. Moving IC2 to BATT+ (architecture.md §9 item 5) belongs in the same revision.
B42: 5. BATT+ now leaves the PCB on a wire: use packs with a protection circuit (or add a PTC), anchor the lead so it cannot chafe or be pinched by the lid gasket, and silkscreen 'BATT' and 'SW' next to the two headers.
B43: 6. The rocker cuts power instantly: firmware must make flash writes (registration data, replay counters) power-loss safe.
B44: 7. Antennas: the Wio-SX1262 also brings its RF out on a U.FL/IPEX socket, so the 868 MHz and 2.4 GHz cables use the same plug. Label them or use different cable lengths so they cannot be swapped at assembly. The 868 MHz antenna is still not in the BoM.
B45: 8. Certification: Espressif certified the WROOM-1U with a 2.33 dBi monopole. A sticker dipole is a different antenna type, which matters for FCC-style module grants; India's WPC requirements for the 2.4 GHz radio were not checked.
